Workbook

Sheet Dashboard
B1: Professional Pharma Sales Dashboard
B2: Executive sales, target achievement, territory, product, and medical representative performance
B3: Reporting period: Jan 2024 - Dec 2024 | Source rows: 1,320
B5: Product | C5: All | D5: Region | E5: All | F5: Medical Rep | G5: All | H5: Month | I5: All | J5: Quarter | K5: All | L5: Year | M5: All
B7: Total Sales Units | D7: Total Sales Value | F7: Total Target Units | H7: Total Target Value | J7: Achievement % | L7: Variance vs Target
B8: =Summary!B4 | D8: =Summary!B5 | F8: =Summary!B6 | H8: =Summary!B7 | J8: =Summary!B8 | L8: =Summary!B9
B10: Products | D10: Medical Reps | F10: Avg Sales per Rep
B11: =Summary!B10 | D11: =Summary!B11 | F11: =Summary!B12
B14: Monthly Sales & Target Trend | H14: Regional Achievement
B28: Product Performance | H28: Medical Representative Ranking
H29: Rank | I29: Medical Rep | J29: Sales Value | K29: Achievement | L29: Gap
H30: =Summary!G66 | I30: =Summary!A66 | J30: =Summary!B66 | K30: =Summary!D66 | L30: =Summary!E66
H31: =Summary!G67 | I31: =Summary!A67 | J31: =Summary!B67 | K31: =Summary!D67 | L31: =Summary!E67
H32: =Summary!G68 | I32: =Summary!A68 | J32: =Summary!B68 | K32: =Summary!D68 | L32: =Summary!E68
H33: =Summary!G69 | I33: =Summary!A69 | J33: =Summary!B69 | K33: =Summary!D69 | L33: =Summary!E69
H34: =Summary!G70 | I34: =Summary!A70 | J34: =Summary!B70 | K34: =Summary!D70 | L34: =Summary!E70
H35: =Summary!G71 | I35: =Summary!A71 | J35: =Summary!B71 | K35: =Summary!D71 | L35: =Summary!E71
H36: =Summary!G72 | I36: =Summary!A72 | J36: =Summary!B72 | K36: =Summary!D72 | L36: =Summary!E72
H37: =Summary!G73 | I37: =Summary!A73 | J37: =Summary!B73 | K37: =Summary!D73 | L37: =Summary!E73
H38: =Summary!G74 | I38: =Summary!A74 | J38: =Summary!B74 | K38: =Summary!D74 | L38: =Summary!E74
H39: =Summary!G75 | I39: =Summary!A75 | J39: =Summary!B75 | K39: =Summary!D75 | L39: =Summary!E75
B40: Smart Insights
B41: Best Region | D41: =Summary!J4
B42: Lowest Region | D42: =Summary!J5
B43: Top Product | D43: =Summary!J6
B44: Top Medical Rep | D44: =Summary!J7
B45: Largest Product Gap | D45: =Summary!J8
B46: Strongest Month | D46: =Summary!J9

Sheet Data
A1: Product Name | B1: Region | C1: Date | D1: Medical Rep | E1: Unit_Price | F1: Sales_Units | G1: Target_Units | H1: Sales Value | I1: Target Value | J1: Month | K1: Month Num | L1: Quarter | M1: Year | N1: Month Date | O1: Achievement % | P1: Variance vs Target
A2: Augmentin 1000 MG | B2: Ismailia | C2: 45292 | D2: Mariam Saeed | E2: 210 | F2: 2799 | G2: 2000 | H2: 587790 | I2: 420000 | J2: Jan | K2: 1 | L2: Q1 | M2: 2024 | N2: 45292 | O2: 1.3995 | P2: 167790
A3: Augmentin 625 MG | B3: Ismailia | C3: 45292 | D3: Mariam Saeed | E3: 117 | F3: 3093 | G3: 3120 | H3: 361881 | I3: 365040 | J3: Jan | K3: 1 | L3: Q1 | M3: 2024 | N3: 45292 | O3: 0.99134615 | P3: -3159
A4: Cataflam 50 MG | B4: Ismailia | C4: 45292 | D4: Mariam Saeed | E4: 86 | F4: 2575 | G4: 2516 | H4: 221450 | I4: 216376 | J4: Jan | K4: 1 | L4: Q1 | M4: 2024 | N4: 45292 | O4: 1.0234499 | P4: 5074
A5: Cataflam 25 MG | B5: Ismailia | C5: 45292 | D5: Mariam Saeed | E5: 34 | F5: 2676 | G5: 2568 | H5: 90984 | I5: 87312 | J5: Jan | K5: 1 | L5: Q1 | M5: 2024 | N5: 45292 | O5: 1.0420561 | P5: 3672
A6: Concor 10 MG | B6: Ismailia | C6: 45292 | D6: Mariam Saeed | E6: 99 | F6: 3500 | G6: 3125 | H6: 346500 | I6: 309375 | J6: Jan | K6: 1 | L6: Q1 | M6: 2024 | N6: 45292 | O6: 1.12 | P6: 37125
A7: Concor 5 MG | B7: Ismailia | C7: 45292 | D7: Mariam Saeed | E7: 72 | F7: 1523 | G7: 2500 | H7: 109656 | I7: 180000 | J7: Jan | K7: 1 | L7: Q1 | M7: 2024 | N7: 45292 | O7: 0.6092 | P7: -70344
A8: Glucophage 1000 MG | B8: Ismailia | C8: 45292 | D8: Mariam Saeed | E8: 126 | F8: 3364 | G8: 3092 | H8: 423864 | I8: 389592 | J8: Jan | K8: 1 | L8: Q1 | M8: 2024 | N8: 45292 | O8: 1.087969 | P8: 34272
A9: Glucophage 500 MG | B9: Ismailia | C9: 45292 | D9: Mariam Saeed | E9: 77 | F9: 2137 | G9: 2117 | H9: 164549 | I9: 163009 | J9: Jan | K9: 1 | L9: Q1 | M9: 2024 | N9: 45292 | O9: 1.0094473 | P9: 1540
A10: Panadol 500 MG | B10: Ismailia | C10: 45292 | D10: Mariam Saeed | E10: 75 | F10: 3022 | G10: 2887 | H10: 226650 | I10: 216525 | J10: Jan | K10: 1 | L10: Q1 | M10: 2024 | N10: 45292 | O10: 1.0467613 | P10: 10125
A11: Panadol 250 MG | B11: Ismailia | C11: 45292 | D11: Mariam Saeed | E11: 45 | F11: 3159 | G11: 3082 | H11: 142155 | I11: 138690 | J11: Jan | K11: 1 | L11: Q1 | M11: 2024 | N11: 45292 | O11: 1.0249838 | P11: 3465
A12: Augmentin 1000 MG | B12: Ismailia | C12: 45323 | D12: Mariam Saeed | E12: 210 | F12: 3174 | G12: 3107 | H12: 666540 | I12: 652470 | J12: Feb | K12: 2 | L12: Q1 | M12: 2024 | N12: 45323 | O12: 1.0215642 | P12: 14070
A13: Augmentin 625 MG | B13: Ismailia | C13: 45323 | D13: Mariam Saeed | E13: 117 | F13: 3680 | G13: 3717 | H13: 430560 | I13: 434889 | J13: Feb | K13: 2 | L13: Q1 | M13: 2024 | N13: 45323 | O13: 0.99004574 | P13: -4329
... A1321: Augmentin 1000 MG | B1321: Sharqia 2 | C1321: 45627 | D1321: Youssef Farouk | E1321: 210 | F1321: 3264 | G1321: 3700 | H1321: 685440 | I1321: 777000 | J1321: Dec | K1321: 12 | L1321: Q4 | M1321: 2024 | N1321: 45627 | O1321: 0.88216216 | P1321: -91560

Sheet Summary
A1: Product Criteria | B1: Region Criteria | C1: Rep Criteria | D1: Month Criteria | E1: Quarter Criteria | F1: Year Criteria | H1: Filtered Total Sales Value
A2: =IF(Dashboard!$C$5="All","*",Dashboard!$C$5) | B2: =IF(Dashboard!$E$5="All","*",Dashboard!$E$5) | C2: =IF(Dashboard!$G$5="All","*",Dashboard!$G$5) | D2: =IF(Dashboard!$I$5="All","*",Dashboard!$I$5) | E2: =IF(Dashboard!$K$5="All","*",Dashboard!$K$5) | F2: =IF(Dashboard!$M$5="All",">0",Dashboard!$M$5)
A4: Total Sales Units | B4: =SUMIFS(salesData[Sales_Units],salesData[Product Name],$A$2,salesData[Region],$B$2,salesData[Medical Rep],$C$2,salesData[Month],$D$2,salesData[Quarter],$E$2,salesData[Year],$F$2) | I4: Best Region | J4: =INDEX(A50:A59,MATCH(MAX(D50:D59),D50:D59,0))
A5: Total Sales Value | B5: =SUMIFS(salesData[Sales Value],salesData[Product Name],$A$2,salesData[Region],$B$2,salesData[Medical Rep],$C$2,salesData[Month],$D$2,salesData[Quarter],$E$2,salesData[Year],$F$2) | I5: Lowest Region | J5: =INDEX(A50:A59,MATCH(MIN(D50:D59),D50:D59,0))
A6: Total Target Units | B6: =SUMIFS(salesData[Target_Units],salesData[Product Name],$A$2,salesData[Region],$B$2,salesData[Medical Rep],$C$2,salesData[Month],$D$2,salesData[Quarter],$E$2,salesData[Year],$F$2) | I6: Top Product | J6: =INDEX(A34:A43,MATCH(MAX(B34:B43),B34:B43,0))
A7: Total Target Value | B7: =SUMIFS(salesData[Target Value],salesData[Product Name],$A$2,salesData[Region],$B$2,salesData[Medical Rep],$C$2,salesData[Month],$D$2,salesData[Quarter],$E$2,salesData[Year],$F$2) | I7: Top Rep | J7: =INDEX(A66:A75,MATCH(MAX(B66:B75),B66:B75,0))
A8: Achievement % | B8: =IFERROR(B5/B7,0) | I8: Largest Target Gap | J8: =INDEX(A34:A43,MATCH(MIN(E34:E43),E34:E43,0))
A9: Variance vs Target | B9: =B5-B7 | I9: Strongest Month | J9: =INDEX(B17:B28,MATCH(MAX(C17:C28),C17:C28,0))
A10: Number of Products | B10: =COUNTA(UNIQUE(FILTER(salesData[Product Name],(salesData[Product Name]<>"")*(IF($A$2="*",1,salesData[Product Name]=$A$2))*(IF($B$2="*",1,salesData[Region]=$B$2))*(IF($C$2="*",1,salesData[Medical Rep]=$C$2))*(IF($D$2="*",1,salesData[Month]=$D$2))*(IF($E$2="*",1,salesData[Quarter]=$E$2))*(IF($F$2=">0",1,salesData[Year]=$F$2)))))
A11: Number of Medical Reps | B11: =COUNTA(UNIQUE(FILTER(salesData[Medical Rep],(salesData[Medical Rep]<>"")*(IF($A$2="*",1,salesData[Product Name]=$A$2))*(IF($B$2="*",1,salesData[Region]=$B$2))*(IF($C$2="*",1,salesData[Medical Rep]=$C$2))*(IF($D$2="*",1,salesData[Month]=$D$2))*(IF($E$2="*",1,salesData[Quarter]=$E$2))*(IF($F$2=">0",1,salesData[Year]=$F$2)))))
A12: Average Sales per Rep | B12: =IFERROR(B5/B11,0)
A16: Month Date | B16: Month | C16: Sales Value | D16: Target Value | E16: Achievement % | F16: MoM Growth %
A17: 45292 | B17: Jan | C17: =SUMIFS(salesData[Sales Value],salesData[Month Date],A17,salesData[Product Name],$A$2,salesData[Region],$B$2,salesData[Medical Rep],$C$2,salesData[Month],$D$2,salesData[Quarter],$E$2,salesData[Year],$F$2) | D17: =SUMIFS(salesData[Target Value],salesData[Month Date],A17,salesData[Product Name],$A$2,salesData[Region],$B$2,salesData[Medical Rep],$C$2,salesData[Month],$D$2,salesData[Quarter],$E$2,salesData[Year],$F$2) | E17: =IFERROR(C17/D17,0) | F17: =NA()
A18: 45323 | B18: Feb | C18: =SUMIFS(salesData[Sales Value],salesData[Month Date],A18,salesData[Product Name],$A$2,salesData[Region],$B$2,salesData[Medical Rep],$C$2,salesData[Month],$D$2,salesData[Quarter],$E$2,salesData[Year],$F$2) | D18: =SUMIFS(salesData[Target Value],salesData[Month Date],A18,salesData[Product Name],$A$2,salesData[Region],$B$2,salesData[Medical Rep],$C$2,salesData[Month],$D$2,salesData[Quarter],$E$2,salesData[Year],$F$2) | E18: =IFERROR(C18/D18,0) | F18: =IFERROR((C18-C17)/C17,0)
A19: 45352 | B19: Mar | C19: =SUMIFS(salesData[Sales Value],salesData[Month Date],A19,salesData[Product Name],$A$2,salesData[Region],$B$2,salesData[Medical Rep],$C$2,salesData[Month],$D$2,salesData[Quarter],$E$2,salesData[Year],$F$2) | D19: =SUMIFS(salesData[Target Value],salesData[Month Date],A19,salesData[Product Name],$A$2,salesData[Region],$B$2,salesData[Medical Rep],$C$2,salesData[Month],$D$2,salesData[Quarter],$E$2,salesData[Year],$F$2) | E19: =IFERROR(C19/D19,0) | F19: =IFERROR((C19-C18)/C18,0)
A20: 45383 | B20: Apr | C20: =SUMIFS(salesData[Sales Value],salesData[Month Date],A20,salesData[Product Name],$A$2,salesData[Region],$B$2,salesData[Medical Rep],$C$2,salesData[Month],$D$2,salesData[Quarter],$E$2,salesData[Year],$F$2) | D20: =SUMIFS(salesData[Target Value],salesData[Month Date],A20,salesData[Product Name],$A$2,salesData[Region],$B$2,salesData[Medical Rep],$C$2,salesData[Month],$D$2,salesData[Quarter],$E$2,salesData[Year],$F$2) | E20: =IFERROR(C20/D20,0) | F20: =IFERROR((C20-C19)/C19,0)
A21: 45413 | B21: May | C21: =SUMIFS(salesData[Sales Value],salesData[Month Date],A21,salesData[Product Name],$A$2,salesData[Region],$B$2,salesData[Medical Rep],$C$2,salesData[Month],$D$2,salesData[Quarter],$E$2,salesData[Year],$F$2) | D21: =SUMIFS(salesData[Target Value],salesData[Month Date],A21,salesData[Product Name],$A$2,salesData[Region],$B$2,salesData[Medical Rep],$C$2,salesData[Month],$D$2,salesData[Quarter],$E$2,salesData[Year],$F$2) | E21: =IFERROR(C21/D21,0) | F21: =IFERROR((C21-C20)/C20,0)
A22: 45444 | B22: Jun | C22: =SUMIFS(salesData[Sales Value],salesData[Month Date],A22,salesData[Product Name],$A$2,salesData[Region],$B$2,salesData[Medical Rep],$C$2,salesData[Month],$D$2,salesData[Quarter],$E$2,salesData[Year],$F$2) | D22: =SUMIFS(salesData[Target Value],salesData[Month Date],A22,salesData[Product Name],$A$2,salesData[Region],$B$2,salesData[Medical Rep],$C$2,salesData[Month],$D$2,salesData[Quarter],$E$2,salesData[Year],$F$2) | E22: =IFERROR(C22/D22,0) | F22: =IFERROR((C22-C21)/C21,0)
A23: 45474 | B23: Jul | C23: =SUMIFS(salesData[Sales Value],salesData[Month Date],A23,salesData[Product Name],$A$2,salesData[Region],$B$2,salesData[Medical Rep],$C$2,salesData[Month],$D$2,salesData[Quarter],$E$2,salesData[Year],$F$2) | D23: =SUMIFS(salesData[Target Value],salesData[Month Date],A23,salesData[Product Name],$A$2,salesData[Region],$B$2,salesData[Medical Rep],$C$2,salesData[Month],$D$2,salesData[Quarter],$E$2,salesData[Year],$F$2) | E23: =IFERROR(C23/D23,0) | F23: =IFERROR((C23-C22)/C22,0)
A24: 45505 | B24: Aug | C24: =SUMIFS(salesData[Sales Value],salesData[Month Date],A24,salesData[Product Name],$A$2,salesData[Region],$B$2,salesData[Medical Rep],$C$2,salesData[Month],$D$2,salesData[Quarter],$E$2,salesData[Year],$F$2) | D24: =SUMIFS(salesData[Target Value],salesData[Month Date],A24,salesData[Product Name],$A$2,salesData[Region],$B$2,salesData[Medical Rep],$C$2,salesData[Month],$D$2,salesData[Quarter],$E$2,salesData[Year],$F$2) | E24: =IFERROR(C24/D24,0) | F24: =IFERROR((C24-C23)/C23,0)
A25: 45536 | B25: Sep | C25: =SUMIFS(salesData[Sales Value],salesData[Month Date],A25,salesData[Product Name],$A$2,salesData[Region],$B$2,salesData[Medical Rep],$C$2,salesData[Month],$D$2,salesData[Quarter],$E$2,salesData[Year],$F$2) | D25: =SUMIFS(salesData[Target Value],salesData[Month Date],A25,salesData[Product Name],$A$2,salesData[Region],$B$2,salesData[Medical Rep],$C$2,salesData[Month],$D$2,salesData[Quarter],$E$2,salesData[Year],$F$2) | E25: =IFERROR(C25/D25,0) | F25: =IFERROR((C25-C24)/C24,0)
A26: 45566 | B26: Oct | C26: =SUMIFS(salesData[Sales Value],salesData[Month Date],A26,salesData[Product Name],$A$2,salesData[Region],$B$2,salesData[Medical Rep],$C$2,salesData[Month],$D$2,salesData[Quarter],$E$2,salesData[Year],$F$2) | D26: =SUMIFS(salesData[Target Value],salesData[Month Date],A26,salesData[Product Name],$A$2,salesData[Region],$B$2,salesData[Medical Rep],$C$2,salesData[Month],$D$2,salesData[Quarter],$E$2,salesData[Year],$F$2) | E26: =IFERROR(C26/D26,0) | F26: =IFERROR((C26-C25)/C25,0)
A27: 45597 | B27: Nov | C27: =SUMIFS(salesData[Sales Value],salesData[Month Date],A27,salesData[Product Name],$A$2,salesData[Region],$B$2,salesData[Medical Rep],$C$2,salesData[Month],$D$2,salesData[Quarter],$E$2,salesData[Year],$F$2) | D27: =SUMIFS(salesData[Target Value],salesData[Month Date],A27,salesData[Product Name],$A$2,salesData[Region],$B$2,salesData[Medical Rep],$C$2,salesData[Month],$D$2,salesData[Quarter],$E$2,salesData[Year],$F$2) | E27: =IFERROR(C27/D27,0) | F27: =IFERROR((C27-C26)/C26,0)
A28: 45627 | B28: Dec | C28: =SUMIFS(salesData[Sales Value],salesData[Month Date],A28,salesData[Product Name],$A$2,salesData[Region],$B$2,salesData[Medical Rep],$C$2,salesData[Month],$D$2,salesData[Quarter],$E$2,salesData[Year],$F$2) | D28: =SUMIFS(salesData[Target Value],salesData[Month Date],A28,salesData[Product Name],$A$2,salesData[Region],$B$2,salesData[Medical Rep],$C$2,salesData[Month],$D$2,salesData[Quarter],$E$2,salesData[Year],$F$2) | E28: =IFERROR(C28/D28,0) | F28: =IFERROR((C28-C27)/C27,0)
A32: Product Performance
A33: Name | B33: Sales Value | C33: Target Value | D33: Achievement % | E33: Variance | F33: Contribution % | G33: Rank
A34: Augmentin 1000 MG | B34: =SUMIFS(salesData[Sales Value],salesData[Product Name],A34,salesData[Product Name],$A$2,salesData[Region],$B$2,salesData[Medical Rep],$C$2,salesData[Month],$D$2,salesData[Quarter],$E$2,salesData[Year],$F$2) | C34: =SUMIFS(salesData[Target Value],salesData[Product Name],A34,salesData[Product Name],$A$2,salesData[Region],$B$2,salesData[Medical Rep],$C$2,salesData[Month],$D$2,salesData[Quarter],$E$2,salesData[Year],$F$2) | D34: =IFERROR(B34/C34,0) | E34: =B34-C34 | F34: =IFERROR(B34/$B$5,0) | G34: =RANK.EQ(B34,B$34:B$43,0)
A35: Glucophage 1000 MG | B35: =SUMIFS(salesData[Sales Value],salesData[Product Name],A35,salesData[Product Name],$A$2,salesData[Region],$B$2,salesData[Medical Rep],$C$2,salesData[Month],$D$2,salesData[Quarter],$E$2,salesData[Year],$F$2) | C35: =SUMIFS(salesData[Target Value],salesData[Product Name],A35,salesData[Product Name],$A$2,salesData[Region],$B$2,salesData[Medical Rep],$C$2,salesData[Month],$D$2,salesData[Quarter],$E$2,salesData[Year],$F$2) | D35: =IFERROR(B35/C35,0) | E35: =B35-C35 | F35: =IFERROR(B35/$B$5,0) | G35: =RANK.EQ(B35,B$34:B$43,0)
A36: Augmentin 625 MG | B36: =SUMIFS(salesData[Sales Value],salesData[Product Name],A36,salesData[Product Name],$A$2,salesData[Region],$B$2,salesData[Medical Rep],$C$2,salesData[Month],$D$2,salesData[Quarter],$E$2,salesData[Year],$F$2) | C36: =SUMIFS(salesData[Target Value],salesData[Product Name],A36,salesData[Product Name],$A$2,salesData[Region],$B$2,salesData[Medical Rep],$C$2,salesData[Month],$D$2,salesData[Quarter],$E$2,salesData[Year],$F$2) | D36: =IFERROR(B36/C36,0) | E36: =B36-C36 | F36: =IFERROR(B36/$B$5,0) | G36: =RANK.EQ(B36,B$34:B$43,0)
A37: Concor 10 MG | B37: =SUMIFS(salesData[Sales Value],salesData[Product Name],A37,salesData[Product Name],$A$2,salesData[Region],$B$2,salesData[Medical Rep],$C$2,salesData[Month],$D$2,salesData[Quarter],$E$2,salesData[Year],$F$2) | C37: =SUMIFS(salesData[Target Value],salesData[Product Name],A37,salesData[Product Name],$A$2,salesData[Region],$B$2,salesData[Medical Rep],$C$2,salesData[Month],$D$2,salesData[Quarter],$E$2,salesData[Year],$F$2) | D37: =IFERROR(B37/C37,0) | E37: =B37-C37 | F37: =IFERROR(B37/$B$5,0) | G37: =RANK.EQ(B37,B$34:B$43,0)
A38: Cataflam 50 MG | B38: =SUMIFS(salesData[Sales Value],salesData[Product Name],A38,salesData[Product Name],$A$2,salesData[Region],$B$2,salesData[Medical Rep],$C$2,salesData[Month],$D$2,salesData[Quarter],$E$2,salesData[Year],$F$2) | C38: =SUMIFS(salesData[Target Value],salesData[Product Name],A38,salesData[Product Name],$A$2,salesData[Region],$B$2,salesData[Medical Rep],$C$2,salesData[Month],$D$2,salesData[Quarter],$E$2,salesData[Year],$F$2) | D38: =IFERROR(B38/C38,0) | E38: =B38-C38 | F38: =IFERROR(B38/$B$5,0) | G38: =RANK.EQ(B38,B$34:B$43,0)
A39: Panadol 500 MG | B39: =SUMIFS(salesData[Sales Value],salesData[Product Name],A39,salesData[Product Name],$A$2,salesData[Region],$B$2,salesData[Medical Rep],$C$2,salesData[Month],$D$2,salesData[Quarter],$E$2,salesData[Year],$F$2) | C39: =SUMIFS(salesData[Target Value],salesData[Product Name],A39,salesData[Product Name],$A$2,salesData[Region],$B$2,salesData[Medical Rep],$C$2,salesData[Month],$D$2,salesData[Quarter],$E$2,salesData[Year],$F$2) | D39: =IFERROR(B39/C39,0) | E39: =B39-C39 | F39: =IFERROR(B39/$B$5,0) | G39: =RANK.EQ(B39,B$34:B$43,0)
A40: Glucophage 500 MG | B40: =SUMIFS(salesData[Sales Value],salesData[Product Name],A40,salesData[Product Name],$A$2,salesData[Region],$B$2,salesData[Medical Rep],$C$2,salesData[Month],$D$2,salesData[Quarter],$E$2,salesData[Year],$F$2) | C40: =SUMIFS(salesData[Target Value],salesData[Product Name],A40,salesData[Product Name],$A$2,salesData[Region],$B$2,salesData[Medical Rep],$C$2,salesData[Month],$D$2,salesData[Quarter],$E$2,salesData[Year],$F$2) | D40: =IFERROR(B40/C40,0) | E40: =B40-C40 | F40: =IFERROR(B40/$B$5,0) | G40: =RANK.EQ(B40,B$34:B$43,0)
A41: Concor 5 MG | B41: =SUMIFS(salesData[Sales Value],salesData[Product Name],A41,salesData[Product Name],$A$2,salesData[Region],$B$2,salesData[Medical Rep],$C$2,salesData[Month],$D$2,salesData[Quarter],$E$2,salesData[Year],$F$2) | C41: =SUMIFS(salesData[Target Value],salesData[Product Name],A41,salesData[Product Name],$A$2,salesData[Region],$B$2,salesData[Medical Rep],$C$2,salesData[Month],$D$2,salesData[Quarter],$E$2,salesData[Year],$F$2) | D41: =IFERROR(B41/C41,0) | E41: =B41-C41 | F41: =IFERROR(B41/$B$5,0) | G41: =RANK.EQ(B41,B$34:B$43,0)
A42: Panadol 250 MG | B42: =SUMIFS(salesData[Sales Value],salesData[Product Name],A42,salesData[Product Name],$A$2,salesData[Region],$B$2,salesData[Medical Rep],$C$2,salesData[Month],$D$2,salesData[Quarter],$E$2,salesData[Year],$F$2) | C42: =SUMIFS(salesData[Target Value],salesData[Product Name],A42,salesData[Product Name],$A$2,salesData[Region],$B$2,salesData[Medical Rep],$C$2,salesData[Month],$D$2,salesData[Quarter],$E$2,salesData[Year],$F$2) | D42: =IFERROR(B42/C42,0) | E42: =B42-C42 | F42: =IFERROR(B42/$B$5,0) | G42: =RANK.EQ(B42,B$34:B$43,0)
A43: Cataflam 25 MG | B43: =SUMIFS(salesData[Sales Value],salesData[Product Name],A43,salesData[Product Name],$A$2,salesData[Region],$B$2,salesData[Medical Rep],$C$2,salesData[Month],$D$2,salesData[Quarter],$E$2,salesData[Year],$F$2) | C43: =SUMIFS(salesData[Target Value],salesData[Product Name],A43,salesData[Product Name],$A$2,salesData[Region],$B$2,salesData[Medical Rep],$C$2,salesData[Month],$D$2,salesData[Quarter],$E$2,salesData[Year],$F$2) | D43: =IFERROR(B43/C43,0) | E43: =B43-C43 | F43: =IFERROR(B43/$B$5,0) | G43: =RANK.EQ(B43,B$34:B$43,0)
A48: Regional Performance
A49: Name | B49: Sales Value | C49: Target Value | D49: Achievement % | E49: Variance | F49: Contribution % | G49: Rank
A50: Ismailia | B50: =SUMIFS(salesData[Sales Value],salesData[Region],A50,salesData[Product Name],$A$2,salesData[Region],$B$2,salesData[Medical Rep],$C$2,salesData[Month],$D$2,salesData[Quarter],$E$2,salesData[Year],$F$2) | C50: =SUMIFS(salesData[Target Value],salesData[Region],A50,salesData[Product Name],$A$2,salesData[Region],$B$2,salesData[Medical Rep],$C$2,salesData[Month],$D$2,salesData[Quarter],$E$2,salesData[Year],$F$2) | D50: =IFERROR(B50/C50,0) | E50: =B50-C50 | F50: =IFERROR(B50/$B$5,0) | G50: =RANK.EQ(B50,B$50:B$59,0)
A51: Sharqia 2 | B51: =SUMIFS(salesData[Sales Value],salesData[Region],A51,salesData[Product Name],$A$2,salesData[Region],$B$2,salesData[Medical Rep],$C$2,salesData[Month],$D$2,salesData[Quarter],$E$2,salesData[Year],$F$2) | C51: =SUMIFS(salesData[Target Value],salesData[Region],A51,salesData[Product Name],$A$2,salesData[Region],$B$2,salesData[Medical Rep],$C$2,salesData[Month],$D$2,salesData[Quarter],$E$2,salesData[Year],$F$2) | D51: =IFERROR(B51/C51,0) | E51: =B51-C51 | F51: =IFERROR(B51/$B$5,0) | G51: =RANK.EQ(B51,B$50:B$59,0)
...

Sheet Lookup
A1: Product Name | B1: Region | C1: Medical Rep | D1: Month | E1: Quarter | F1: Year
A2: All | B2: All | C2: All | D2: All | E2: All | F2: All
A3: Augmentin 1000 MG | B3: Alexandria 1 | C3: Ahmed Hassan | D3: Jan | E3: Q1 | F3: 2024
A4: Augmentin 625 MG | B4: Alexandria 2 | C4: Amira Mostafa | D4: Feb | E4: Q2
A5: Cataflam 25 MG | B5: Cairo 1 | C5: Fatma Ali | D5: Mar | E5: Q3
A6: Cataflam 50 MG | B6: Cairo 2 | C6: Hassan El-Shamy | D6: Apr | E6: Q4
A7: Concor 10 MG | B7: Dakahlia 1 | C7: Mariam Saeed | D7: May
A8: Concor 5 MG | B8: Dakahlia 2 | C8: Mohamed Mahmoud | D8: Jun
A9: Glucophage 1000 MG | B9: Ismailia | C9: Nour El-Din | D9: Jul
A10: Glucophage 500 MG | B10: Sharqia 1 | C10: Omar Khaled | D10: Aug
A11: Panadol 250 MG | B11: Sharqia 2 | C11: Sara Ibrahim | D11: Sep
A12: Panadol 500 MG | B12: Suez | C12: Youssef Farouk | D12: Oct
D13: Nov
D14: Dec

Sheet Measures & Formulas
A1: Metric | B1: Excel Formula / Logic | C1: Power BI DAX Measure | D1: Business Meaning
A2: Total Sales Units | B2: '=SUM(salesData[Sales_Units]) | C2: Total Sales Units = SUM(salesData[Sales_Units]) | D2: Total physical units sold.
A3: Total Sales Value | B3: '=SUM(salesData[Sales Value]) | C3: Total Sales Value = SUM(salesData[sale value]) | D3: Gross actual sales value.
A4: Total Target Units | B4: '=SUM(salesData[Target_Units]) | C4: Total Target Units = SUM(salesData[Target_Units]) | D4: Planned sales units.
A5: Total Target Value | B5: '=SUM(salesData[Target Value]) | C5: Total Target Value = SUM(salesData[target value]) | D5: Planned sales value.
A6: Achievement % | B6: '=Total Sales Value / Total Target Value | C6: Achievement % = DIVIDE([Total Sales Value], [Total Target Value]) | D6: Target delivery ratio.
A7: Variance vs Target | B7: '=Total Sales Value - Total Target Value | C7: Variance vs Target = [Total Sales Value] - [Total Target Value] | D7: Absolute over/under-performance.
A8: Variance % | B8: '=Variance vs Target / Total Target Value | C8: Variance % = DIVIDE([Variance vs Target], [Total Target Value]) | D8: Relative over/under-performance.
A9: Number of Products | B9: '=COUNTA(UNIQUE(salesData[Product Name])) | C9: Number of Products = DISTINCTCOUNT(salesData[product name]) | D9: Portfolio breadth in current filter context.
A10: Number of Medical Reps | B10: '=COUNTA(UNIQUE(salesData[Medical Rep])) | C10: Number of Medical Representatives = DISTINCTCOUNT(salesData[Medical_Rep]) | D10: Active sales-force count.
A11: Average Sales per Rep | B11: '=Total Sales Value / Number of Medical Reps | C11: Average Sales per Rep = DIVIDE([Total Sales Value], [Number of Medical Representatives]) | D11: Productivity indicator.
A12: Sales Contribution % | B12: '=Entity Sales / Total Sales | C12: Sales Contribution % = DIVIDE([Total Sales Value], CALCULATE([Total Sales Value], ALL(salesData))) | D12: Portfolio, region, or rep contribution.
... A14: Rep Rank | B14: '=RANK.EQ(Rep Sales, All Rep Sales, 0) | C14: Rep Rank = RANKX(ALL(salesData[Medical_Rep]), [Total Sales Value], , DESC) | D14: Dynamic sales-force ranking.

Sheet Guide
A1: Professional Pharma Sales Dashboard - Guide
A3: Dashboard Overview | B3: This workbook provides an executive pharma sales dashboard with KPI cards, trend analysis, product, region, and medical representative performance views.
A4: How to Use Filters | B4: Use the dropdowns on the Dashboard header to filter Product, Region, Medical Rep, Month, Quarter, and Year. Charts and KPIs recalculate in Excel.
A5: Data Source | B5: The Data sheet contains the cleaned salesData table from the original workbook. The original workbook was not overwritten.
A6: Performance Segmentation | B6: Achievement values at or above 100% are strong, 90%-99.9% need monitoring, and below 90% require management attention.
A7: Executive Recommendations | B7: Prioritize products and reps with high sales value but below-target achievement; use regional gaps to guide coaching and allocation decisions.
A8: Future Enhancements | B8: Power BI migration, forecast projection, therapy-area segmentation, territory hierarchy, CRM activity integration, and automated refresh.
